<?xml version="1.0" ?>
<robot name="transformer">
  <material name="yellow">
    <color rgba="1 0.95 0 1"/>
  </material>
  <material name="blue">
    <color rgba="0 0 1 1"/>
  </material>
  <material name="light_blue">
    <color rgba="0 0.5 0.8 1"/>
  </material>
  <material name="black">
    <color rgba="0 0 0 1"/>
  </material>
  <material name="white">
    <color rgba="1 1 1 1"/>
  </material>
  <material name="red">
    <color rgba="0.8 0.0 0.0 1.0"/>
  </material>
  <material name="silver">
    <color rgba="0.79 0.82 0.93 1"/>
  </material>
  <material name="dark_grey">
    <color rgba="0.3 0.3 0.3 1"/>
  </material>

  <!-- Base-Footprint -->
  <!-- base_footprint is a fictitious link(frame) that is on the ground right below base_link origin -->
  <link name="base_footprint"/>
  <!-- Joint to connect base_footprint with base_link -->
  <joint name="base_footprint_joint" type="fixed">
    <parent link="base_link"/>
    <child link="base_footprint"/>
    <origin rpy="0 0 0" xyz="0 0 -0.0501"/>
  </joint>
  <link name="base_link">
    <inertial>
      <mass value="0.8"/>
      <inertia ixx="0.00042833333333333335" ixy="0.0" ixz="0.0" iyy="0.0025366666666666667" iyz="0.0" izz="0.002961666666666667"/>
      <origin rpy="0.0 0.0 0.0" xyz="0.0 0.0 0.0"/>
    </inertial>
    <visual>
      <origin rpy="0 0 0" xyz="0 0 0"/>
      <geometry>
        <mesh filename="package://andino_description/meshes/andino/chassis.stl"/>
      </geometry>
      <material name="blue"/>
    </visual>
    <collision>
      <origin rpy="0.0 0.0 0.0" xyz="0.0 0.0 0.0"/>
      <geometry>
        <box size="0.195 0.08 0.005"/>
      </geometry>
    </collision>
  </link>
  <link name="second_base_link">
    <inertial>
      <mass value="0.8"/>
      <inertia ixx="0.00042833333333333335" ixy="0.0" ixz="0.0" iyy="0.0025366666666666667" iyz="0.0" izz="0.002961666666666667"/>
      <origin rpy="0.0 0.0 0.0" xyz="0.0 0.0 0.0"/>
    </inertial>
    <visual>
      <origin rpy="0 0 0" xyz="0 0 0.05"/>
      <geometry>
        <mesh filename="package://andino_description/meshes/andino/chassis_top.stl"/>
      </geometry>
      <material name="blue"/>
    </visual>
    <collision>
      <origin rpy="0.0 0.0 0.0" xyz="0.0 0.0 0.0"/>
      <geometry>
        <box size="0.195 0.08 0.005"/>
      </geometry>
    </collision>
  </link>
  <!-- Joint to connect second_story with base_link -->
  <joint name="second_base_joint" type="fixed">
    <parent link="base_link"/>
    <child link="second_base_link"/>
    <origin rpy="0 0 0" xyz="0 0 0"/>
  </joint>
  <link name="caster_base_link">
    <inertial>
      <mass value="0.02"/>
      <inertia ixx="5.333333333333334e-06" ixy="0.0" ixz="0.0" iyy="5.333333333333334e-06" iyz="0.0" izz="5.333333333333334e-06"/>
      <origin rpy="0.0 0.0 0.0" xyz="0.0 0.0 -0.02"/>
    </inertial>
    <visual>
      <origin rpy="0 0 0" xyz="0 0 -0.02"/>
      <geometry>
        <mesh filename="package://andino_description/meshes/andino/caster_base.stl"/>
      </geometry>
      <material name="silver"/>
    </visual>
    <collision>
      <origin rpy="0 0 0" xyz="0 0 -0.02"/>
      <geometry>
        <box size="0.04 0.04 0.04"/>
      </geometry>
    </collision>
  </link>
  <joint name="caster_base_joint" type="fixed">
    <origin rpy="0 0 0" xyz="-0.076 -0.0 0.0045"/>
    <parent link="base_link"/>
    <child link="caster_base_link"/>
    <axis xyz="0 0 1"/>
    <dynamics damping="0.01" friction="0.0"/>
  </joint>
  <!-- caster hub -->
  <link name="caster_rotation_link">
    <inertial>
      <mass value="0.02"/>
      <inertia ixx="5.333333333333334e-06" ixy="0.0" ixz="0.0" iyy="5.333333333333334e-06" iyz="0.0" izz="5.333333333333334e-06"/>
      <origin rpy="0.0 0.0 0.0" xyz="0.0 0.0 -0.02"/>
    </inertial>
    <visual>
      <origin rpy="0 0 0" xyz="0 0 -0.02"/>
      <geometry>
        <mesh filename="package://andino_description/meshes/andino/caster_wheel_support.stl"/>
      </geometry>
      <material name="silver"/>
    </visual>
    <collision>
      <origin rpy="0 0 0" xyz="0 0 -0.02"/>
      <geometry>
        <box size="0.04 0.04 0.04"/>
      </geometry>
    </collision>
  </link>
  <joint name="caster_rotation_joint" type="fixed">
    <origin rpy="0 0 0" xyz="-0.077 -0.0 0.0045"/>
    <parent link="base_link"/>
    <child link="caster_rotation_link"/>
    <axis xyz="0 0 1"/>
    <dynamics damping="0.01" friction="0.0"/>
  </joint>
  <!-- caster wheel -->
  <link name="caster_wheel_link">
    <inertial>
      <mass value="0.5"/>
      <inertia ixx="3.229166666666667e-05" ixy="0" ixz="0" iyy="3.229166666666667e-05" iyz="0" izz="5.625e-05"/>
      <origin rpy="0.0 0.0 0.0" xyz="0.0 0.0 0.0"/>
    </inertial>
    <visual>
      <origin rpy="0 0 0" xyz="0 0 0"/>
      <geometry>
        <mesh filename="package://andino_description/meshes/andino/caster_wheel.stl"/>
      </geometry>
      <material name="black"/>
    </visual>
    <collision>
      <origin rpy="1.5707963267948966 0 0" xyz="0 0 0"/>
      <geometry>
        <cylinder length="0.01" radius="0.015"/>
      </geometry>
    </collision>
  </link>
  <joint name="caster_wheel_joint" type="fixed">
    <origin rpy="0 0 0" xyz="-0.016 0 -0.04"/>
    <parent link="caster_rotation_link"/>
    <child link="caster_wheel_link"/>
    <axis xyz="0 1 0"/>
  </joint>
  <link name="right_wheel">
    <visual>
      <origin rpy="1.5707963267948966 0 -3.141592653589793" xyz="0.0 0 0"/>
      <geometry>
        <mesh filename="package://andino_description/meshes/andino/../components/wheel.stl"/>
      </geometry>
      <material name="dark_grey"/>
    </visual>
    <collision>
      <origin rpy="1.5707963267948966 0 0" xyz="0 0 0"/>
      <geometry>
        <cylinder length="0.025" radius="0.0331"/>
      </geometry>
    </collision>
    <inertial>
      <mass value="0.032"/>
      <inertia ixx="1.0431546666666667e-05" ixy="0" ixz="0" iyy="1.0431546666666667e-05" iyz="0" izz="1.7529759999999997e-05"/>
      <origin rpy="1.5707963267948966 0.0 0.0" xyz="0.0 0.0 0.0"/>
    </inertial>
  </link>
  <joint name="right_wheel_joint" type="continuous">
    <axis rpy="0 0 0" xyz="0 1 0"/>
    <parent link="base_link"/>
    <child link="right_wheel"/>
    <origin rpy="0 0 0" xyz="0.018500000000000003 -0.0675 -0.017"/>
    <dynamics damping="0.01" friction="0.0"/>
  </joint>
  <link name="left_wheel">
    <visual>
      <origin rpy="1.5707963267948966 0 0.0" xyz="0.0 0 0"/>
      <geometry>
        <mesh filename="package://andino_description/meshes/andino/../components/wheel.stl"/>
      </geometry>
      <material name="dark_grey"/>
    </visual>
    <collision>
      <origin rpy="1.5707963267948966 0 0" xyz="0 0 0"/>
      <geometry>
        <cylinder length="0.025" radius="0.0331"/>
      </geometry>
    </collision>
    <inertial>
      <mass value="0.032"/>
      <inertia ixx="1.0431546666666667e-05" ixy="0" ixz="0" iyy="1.0431546666666667e-05" iyz="0" izz="1.7529759999999997e-05"/>
      <origin rpy="1.5707963267948966 0.0 0.0" xyz="0.0 0.0 0.0"/>
    </inertial>
  </link>
  <joint name="left_wheel_joint" type="continuous">
    <axis rpy="0 0 0" xyz="0 1 0"/>
    <parent link="base_link"/>
    <child link="left_wheel"/>
    <origin rpy="0 0 0" xyz="0.018500000000000003 0.0675 -0.017"/>
    <dynamics damping="0.01" friction="0.0"/>
  </joint>
  <link name="right_motor">
    <visual>
      <origin rpy="0.0 0 -3.141592653589793" xyz="0.0 0.0 0.0"/>
      <geometry>
        <mesh filename="package://andino_description/meshes/andino/motor.stl"/>
      </geometry>
      <material name="light_blue"/>
    </visual>
    <collision>
      <origin rpy="1.5707963267948966 0 0" xyz="0 0 0"/>
      <geometry>
        <box size="0.07 0.0225 0.0188"/>
      </geometry>
    </collision>
    <inertial>
      <mass value="0.1"/>
      <inertia ixx="7.164083333333333e-06" ixy="0.0" ixz="0.0" iyy="4.3778666666666675e-05" iyz="0.0" izz="4.505208333333334e-05"/>
      <origin rpy="0.0 0.0 0.0" xyz="0.0 0.0 0.0"/>
    </inertial>
  </link>
  <joint name="right_motor_joint" type="fixed">
    <parent link="base_link"/>
    <child link="right_motor"/>
    <origin rpy="0 3.141592653589793 0" xyz="0.0015000000000000013 -0.037750000000000006 -0.017"/>
    <axis rpy="0 0 0" xyz="0 1 0"/>
  </joint>
  <link name="left_motor">
    <visual>
      <origin rpy="0.0 0 0.0" xyz="0.0 0.0 0.0"/>
      <geometry>
        <mesh filename="package://andino_description/meshes/andino/motor.stl"/>
      </geometry>
      <material name="light_blue"/>
    </visual>
    <collision>
      <origin rpy="1.5707963267948966 0 0" xyz="0 0 0"/>
      <geometry>
        <box size="0.07 0.0225 0.0188"/>
      </geometry>
    </collision>
    <inertial>
      <mass value="0.1"/>
      <inertia ixx="7.164083333333333e-06" ixy="0.0" ixz="0.0" iyy="4.3778666666666675e-05" iyz="0.0" izz="4.505208333333334e-05"/>
      <origin rpy="0.0 0.0 0.0" xyz="0.0 0.0 0.0"/>
    </inertial>
  </link>
  <joint name="left_motor_joint" type="fixed">
    <parent link="base_link"/>
    <child link="left_motor"/>
    <origin rpy="0 -0.0 0" xyz="0.0015000000000000013 0.037750000000000006 -0.017"/>
    <axis rpy="0 0 0" xyz="0 1 0"/>
  </joint>
  <link name="rplidar_laser_link">
    <visual>
      <origin rpy="0 0 3.141592653589793" xyz="0 0 0"/>
      <geometry>
        <mesh filename="package://andino_description/meshes/sensors/rplidar-a1.stl"/>
      </geometry>
      <material name="dark_grey"/>
    </visual>
    <collision>
      <origin rpy="0 0 0" xyz="0 0 0"/>
      <geometry>
        <cylinder length="0.01" radius="0.015"/>
      </geometry>
    </collision>
    <inertial>
      <mass value="0.1"/>
      <inertia ixx="6.458333333333333e-06" ixy="0" ixz="0" iyy="6.458333333333333e-06" iyz="0" izz="1.1249999999999999e-05"/>
      <origin rpy="0 0 0" xyz="0 0 0"/>
    </inertial>
  </link>
  <joint name="rplidar_laser_joint" type="fixed">
    <parent link="second_base_link"/>
    <child link="rplidar_laser_link"/>
    <origin rpy="0 0 3.141592653589793" xyz="0.05 0.0 0.08"/>
    <axis xyz="0 1 0"/>
  </joint>
  <link name="camera_link">
    <visual>
      <origin rpy="0 0 0" xyz="0 0 0"/>
      <geometry>
        <mesh filename="package://andino_description/meshes/sensors/camera_mount.stl"/>
      </geometry>
      <material name="blue"/>
    </visual>
    <collision>
      <origin rpy="0 0 0" xyz="0 0 0"/>
      <geometry>
        <box size="0.02 0.02 0.02"/>
      </geometry>
    </collision>
    <inertial>
      <mass value="0.1"/>
      <inertia ixx="6.666666666666667e-06" ixy="0.0" ixz="0.0" iyy="6.666666666666667e-06" iyz="0.0" izz="6.666666666666667e-06"/>
      <origin rpy="0 0 0" xyz="0 0 0"/>
    </inertial>
  </link>
  <joint name="camera_joint" type="fixed">
    <parent link="base_link"/>
    <child link="camera_link"/>
    <origin rpy="0 0 0" xyz="0.085 0.0 0.025"/>
    <axis xyz="0 1 0"/>
  </joint>






  <link name="link_1">
    <origin rpy="0 0 0" xyz="0 0 0"/>
    <inertial>
      <origin rpy="0.0                      0.0                      0.0" xyz="-0.022706                      0.04294                      -0.12205"/>
      <mass value="0.88065"/>
      <inertia ixx="0.0034" ixy="0.00042296" ixz="-0.00089231" iyy="0.0041778" iyz="0.0010848" izz="0.0027077"/>
    </inertial>
    <visual>
      <origin rpy="0 0 0" xyz="0 0 0"/>
      <geometry>
        <mesh filename="package://urdf_and_tf/meshes/link_1.STL"/>
      </geometry>
      <material name="">
        <color rgba="1 1 0 1"/>
      </material>
    </visual>
    <collision>
      <origin rpy="0 0 0" xyz="0 0 0"/>
      <geometry>
        <mesh filename="package://urdf_and_tf/meshes/link_1.STL"/>
      </geometry>
    </collision>
  </link>
  <joint name="joint_1" type="revolute">
    <origin rpy="3.141592653589793 0 0" xyz="-0.05 0 0.053445"/>
    <parent link="second_base_link"/>
    <child link="link_1"/>
    <axis xyz="0 0 1"/>
    <limit effort="100" lower="-2.96706" upper="2.96706" velocity="100"/>
  </joint>
  <link name="link_2">
    <origin rpy="0 0 0" xyz="0 0 0"/>
    <inertial>
      <origin rpy="0.0                      0.0                      0.0" xyz="0.064818                      -0.11189                      -0.038671"/>
      <mass value="0.57738"/>
      <inertia ixx="0.0047312" ixy="0.0022624" ixz="0.00032144" iyy="0.0020836" iyz="-0.00056569" izz="0.0056129"/>
    </inertial>
    <visual>
      <origin rpy="0 0 0" xyz="0 0 0"/>
      <geometry>
        <mesh filename="package://urdf_and_tf/meshes/link_2.STL"/>
      </geometry>
      <material name="">
        <color rgba="1 1 0 1"/>
      </material>
    </visual>
    <collision>
      <origin rpy="0 0 0" xyz="0 0 0"/>
      <geometry>
        <mesh filename="package://urdf_and_tf/meshes/link_2.STL"/>
      </geometry>
    </collision>
  </link>
  <joint name="joint_2" type="revolute">
    <origin rpy="1.5708 0.5236 -1.5708" xyz="0 0.064146 -0.16608"/>
    <parent link="link_1"/>
    <child link="link_2"/>
    <axis xyz="0 0 -1"/>
    <limit effort="100" lower="-0.6911503837897545" upper="1.5707963267948966" velocity="100"/>
  </joint>
  <link name="link_3">
    <origin rpy="0 0 0" xyz="0 0 0"/>
    <inertial>
      <origin rpy="0.0                      0.0                      0.0" xyz="-0.00029765                      -0.023661                      -0.0019125"/>
      <mass value="0.1787"/>
      <inertia ixx="0.0001685" ixy="-2.7713e-05" ixz="5.6885e-06" iyy="0.00012865" iyz="2.9256e-05" izz="0.00020744"/>
    </inertial>
    <visual>
      <origin rpy="0 0 0" xyz="0 0 0"/>
      <geometry>
        <mesh filename="package://urdf_and_tf/meshes/link_3.STL"/>
      </geometry>
      <material name="">
        <color rgba="1 1 0 1"/>
      </material>
    </visual>
    <collision>
      <origin rpy="0 0 0" xyz="0 0 0"/>
      <geometry>
        <mesh filename="package://urdf_and_tf/meshes/link_3.STL"/>
      </geometry>
    </collision>
  </link>
  <joint name="joint_3" type="revolute">
    <origin rpy="0 0 -1.04720367321" xyz="0.1525 -0.26414 0"/>
    <parent link="link_2"/>
    <child link="link_3"/>
    <axis xyz="0 0 -1"/>
    <limit effort="100" lower="0.0174533" upper="2.5080381" velocity="100"/>
  </joint>
  <link name="link_4">
    <origin rpy="0 0 0" xyz="0 0 0"/>
    <inertial>
      <origin rpy="0.0                      0.0                      0.0" xyz="-0.0016798                      0.00057319                      -0.074404"/>
      <mass value="0.34936"/>
      <inertia ixx="0.0030532" ixy="-1.8615e-05" ixz="-7.0047e-05" iyy="0.0031033" iyz="2.3301e-05" izz="0.00022264"/>
    </inertial>
    <visual>
      <origin rpy="0 0 0" xyz="0 0 0"/>
      <geometry>
        <mesh filename="package://urdf_and_tf/meshes/link_4.STL"/>
      </geometry>
      <material name="">
        <color rgba="1 1 0 1"/>
      </material>
    </visual>
    <collision>
      <origin rpy="0 0 0" xyz="0 0 0"/>
      <geometry>
        <mesh filename="package://urdf_and_tf/meshes/link_4.STL"/>
      </geometry>
    </collision>
  </link>
  <joint name="joint_4" type="revolute">
    <origin rpy="1.5708 -1.2554 -1.5708" xyz="0 0 0.00675"/>
    <parent link="link_3"/>
    <child link="link_4"/>
    <axis xyz="0 0 -1"/>
    <limit effort="100" lower="-2.8710666" upper="2.8710666" velocity="100"/>
  </joint>
  <link name="link_5">
    <origin rpy="0 0 0" xyz="0 0 0"/>
    <inertial>
      <origin rpy="0.0                      0.0                      0.0" xyz="0.0015066                      -1.3102e-05                      -0.012585"/>
      <mass value="0.11562"/>
      <inertia ixx="5.5035e-05" ixy="-1.019e-08" ixz="-2.6243e-06" iyy="8.2921e-05" iyz="1.4437e-08" izz="5.2518e-05"/>
    </inertial>
    <visual>
      <origin rpy="0 0 0" xyz="0 0 0"/>
      <geometry>
        <mesh filename="package://urdf_and_tf/meshes/link_5.STL"/>
      </geometry>
      <material name="">
        <color rgba="1 1 0 1"/>
      </material>
    </visual>
    <collision>
      <origin rpy="0 0 0" xyz="0 0 0"/>
      <geometry>
        <mesh filename="package://urdf_and_tf/meshes/link_5.STL"/>
      </geometry>
    </collision>
  </link>
  <joint name="joint_5" type="revolute">
    <origin rpy="3.141592653589793 0 -2.8262" xyz="0 0 -0.22225"/>
    <parent link="link_4"/>
    <child link="link_5"/>
    <axis xyz="1 0 0"/>
    <limit effort="100" lower="-1.81776042" upper="1.81776042" velocity="100"/>
  </joint>
  <link name="link_6">
    <origin rpy="0 0 0" xyz="0 0 0"/>
    <inertial>
      <origin rpy="0.0                      0.0                      0.0" xyz="2.9287e-10                      -1.6472e-09                      0.0091432"/>
      <mass value="0.013863"/>
      <inertia ixx="1.3596e-06" ixy="3.0585e-13" ixz="5.7102e-14" iyy="1.7157e-06" iyz="6.3369e-09" izz="2.4332e-06"/>
    </inertial>
    <visual>
      <origin rpy="0 0 0" xyz="0 0 0"/>
      <geometry>
        <mesh filename="package://urdf_and_tf/meshes/link_6.STL"/>
      </geometry>
      <material name="">
        <color rgba="1 1 0 1"/>
      </material>
    </visual>
    <collision>
      <origin rpy="0 0 0" xyz="0 0 0"/>
      <geometry>
        <mesh filename="package://urdf_and_tf/meshes/link_6.STL"/>
      </geometry>
    </collision>
  </link>
  <joint name="joint_6" type="revolute">
    <origin rpy="0 0 3.1416" xyz="-0.000294 0 0.02117"/>
    <parent link="link_5"/>
    <child link="link_6"/>
    <axis xyz="0 0 1"/>
    <limit effort="100" lower="-2.5848326" upper="2.5848326" velocity="100"/>
  </joint>
</robot>
